Workbook

Sheet Formato Cronograma
A1: Cronograma de Actividades Proyecto N° 638 - 2026 - ADRES - UNAL | N1: ENERO | AO1: FEBRERO | BM1: MARZO | CM1: ABRIL | DM1: MAYO | EM1: JUNIO | FM1: JULIO | GN1: AGOSTO | HN1: SEPTIEMBRE | IN1: OCTUBRE | JO1: NOVIEMBRE | KN1: DICIEMBRE
N2: Ju. | O2: Vi. | P2: Sa. | Q2: Lu. | R2: Ma. | S2: Mi. | T2: Ju. | U2: Vi. | V2: Sa. | W2: Lu. | X2: Ma. | Y2: Mi. | Z2: Ju. | AA2: Vi. | AB2: Sa. | AC2: Lu. | AD2: Ma. | AE2: Mi. | AF2: Ju. | AG2: Vi. | AH2: Sa. | AI2: Lu. | AJ2: Ma. | AK2: Mi. | AL2: Ju. | AM2: Vi. | AN2: Sa. | AO2: Lu. | AP2: Ma. | AQ2: Mi. | AR2: Ju. | AS2: Vi. | AT2: Sa. | AU2: Lu. | AV2: Ma. | AW2: Mi. | AX2: Ju. | AY2: Vi. | AZ2: Sa. | BA2: Lu. | BB2: Ma. | BC2: Mi. | BD2: Ju. | BE2: Vi. | BF2: Sa. | BG2: Lu. | BH2: Ma. | BI2: Mi. | BJ2: Ju. | BK2: Vi. | BL2: Sa. | BM2: Lu. | BN2: Ma. | BO2: Mi. | BP2: Ju. | BQ2: Vi. | BR2: Sa. | BS2: Lu. | BT2: Ma. | BU2: Mi. | BV2: Ju. | BW2: Vi. | BX2: Sa. | BY2: Lu. | BZ2: Ma. | CA2: Mi. | CB2: Ju. | CC2: Vi. | CD2: Sa. | CE2: Lu. | CF2: Ma. | CG2: Mi. | CH2: Ju. | CI2: Vi. | CJ2: Sa. | CK2: Lu. | CL2: Ma. | CM2: Mi. | CN2: Ju. | CO2: Vi. | CP2: Sa. | CQ2: Lu. | CR2: Ma. | CS2: Mi. | CT2: Ju. | CU2: Vi. | CV2: Sa. | CW2: Lu. | CX2: Ma. | CY2: Mi. | CZ2: Ju. | DA2: Vi. | DB2: Sa. | DC2: Lu. | DD2: Ma. | DE2: Mi. | DF2: Ju. | DG2: Vi. | DH2: Sa. | DI2: Lu. | DJ2: Ma. | DK2: Mi. | DL2: Ju. | DM2: Vi. | DN2: Sa. | DO2: Lu. | DP2: Ma. | DQ2: Mi. | DR2: Ju. | DS2: Vi. | DT2: Sa. | DU2: Lu. | DV2: Ma. | DW2: Mi. | DX2: Ju. | DY2: Vi. | DZ2: Sa. | EA2: Lu. | EB2: Ma. | EC2: Mi. | ED2: Ju. | EE2: Vi. | EF2: Sa. | EG2: Lu. | EH2: Ma. | EI2: Mi. | EJ2: Ju. | EK2: Vi. | EL2: Sa. | EM2: Lu. | EN2: Ma. | EO2: Mi. | EP2: Ju. | EQ2: Vi. | ER2: Sa. | ES2: Lu. | ET2: Ma. | EU2: Mi. | EV2: Ju. | EW2: Vi. | EX2: Sa. | EY2: Lu. | EZ2: Ma. | FA2: Mi. | FB2: Ju. | FC2: Vi. | FD2: Sa. | FE2: Lu. | FF2: Ma. | FG2: Mi. | FH2: Ju. | FI2: Vi. | FJ2: Sa. | FK2: Lu. | FL2: Ma. | FM2: Mi. | FN2: Ju. | FO2: Vi. | FP2: Sa. | FQ2: Lu. | FR2: Ma. | FS2: Mi. | FT2: Ju. | FU2: Vi. | FV2: Sa. | FW2: Lu. | FX2: Ma. | FY2: Mi. | FZ2: Ju. | GA2: Vi. | GB2: Sa. | GC2: Lu. | GD2: Ma. | GE2: Mi. | GF2: Ju. | GG2: Vi. | GH2: Sa. | GI2: Lu. | GJ2: Ma. | GK2: Mi. | GL2: Ju. | GM2: Vi. | GN2: Sa. | GO2: Lu. | GP2: Ma. | GQ2: Mi. | GR2: Ju. | GS2: Vi. | GT2: Sa. | GU2: Lu. | GV2: Ma. | GW2: Mi. | GX2: Ju. | GY2: Vi. | GZ2: Sa. | HA2: Lu. | HB2: Ma. | HC2: Mi. | HD2: Ju. | HE2: Vi. | HF2: Sa. | HG2: Lu. | HH2: Ma. | HI2: Mi. | HJ2: Ju. | HK2: Vi. | HL2: Sa. | HM2: Lu. | HN2: Ma. | HO2: Mi. | HP2: Ju. | HQ2: Vi. | HR2: Sa. | HS2: Lu. | HT2: Ma. | HU2: Mi. | HV2: Ju. | HW2: Vi. | HX2: Sa. | HY2: Lu. | HZ2: Ma. | IA2: Mi. | IB2: Ju. | IC2: Vi. | ID2: Sa. | IE2: Lu. | IF2: Ma. | IG2: Mi. | IH2: Ju. | II2: Vi. | IJ2: Sa. | IK2: Lu. | IL2: Ma. | IM2: Mi. | IN2: Ju. | IO2: Vi. | IP2: Sa. | IQ2: Lu. | IR2: Ma. | IS2: Mi. | IT2: Ju. | IU2: Vi. | IV2: Sa. | IW2: Lu. | IX2: Ma. | IY2: Mi. | IZ2: Ju. | JA2: Vi. | JB2: Sa. | JC2: Lu. | JD2: Ma. | JE2: Mi. | JF2: Ju. | JG2: Vi. | JH2: Sa. | JI2: Lu. | JJ2: Ma. | JK2: Mi. | JL2: Ju. | JM2: Vi. | JN2: Sa. | JO2: Lu. | JP2: Ma. | JQ2: Mi. | JR2: Ju. | JS2: Vi. | JT2: Sa. | JU2: Lu. | JV2: Ma. | JW2: Mi. | JX2: Ju. | JY2: Vi. | JZ2: Sa. | KA2: Lu. | KB2: Ma. | KC2: Mi. | KD2: Ju. | KE2: Vi. | KF2: Sa. | KG2: Lu. | KH2: Ma. | KI2: Mi. | KJ2: Ju. | KK2: Vi. | KL2: Sa. | KM2: Lu. | KN2: Ma. | KO2: Mi. | KP2: Ju. | KQ2: Vi. | KR2: Sa. | KS2: Lu. | KT2: Ma. | KU2: Mi. | KV2: Ju. | KW2: Vi. | KX2: Sa. | KY2: Lu. | KZ2: Ma. | LA2: Mi. | LB2: Ju. | LC2: Vi. | LD2: Sa. | LE2: Lu. | LF2: Ma. | LG2: Mi. | LH2: Ju. | LI2: Vi. | LJ2: Sa. | LK2: Lu. | LL2: Ma. | LM2: Mi. | LN2: Ju.
A3: Ítem | B3: Eje | C3: Actividad Académica | D3: Valor | E3: Tipología | F3: Docentes | G3: No. Participantes | H3: No. Certificados | I3: No. Horas P: Presencial V: Virtual | J3: No. Sesiones P: Presencial V: Virtual | K3: Fecha de Inicio | L3: Fecha de Terminación | M3: Horario P: Presencial V: Virtual | N3: 1 | O3: 2 | P3: 3 | Q3: 5 | R3: 6 | S3: 7 | T3: 8 | U3: 9 | V3: 10 | W3: 12 | X3: 13 | Y3: 14 | Z3: 15 | AA3: 16 | AB3: 17 | AC3: 19 | AD3: 20 | AE3: 21 | AF3: 22 | AG3: 23 | AH3: 24 | AI3: 26 | AJ3: 27 | AK3: 28 | AL3: 29 | AM3: 30 | AN3: 31 | AO3: 2 | AP3: 3 | AQ3: 4 | AR3: 5 | AS3: 6 | AT3: 7 | AU3: 9 | AV3: 10 | AW3: 11 | AX3: 12 | AY3: 13 | AZ3: 14 | BA3: 16 | BB3: 17 | BC3: 18 | BD3: 19 | BE3: 20 | BF3: 21 | BG3: 23 | BH3: 24 | BI3: 25 | BJ3: 26 | BK3: 27 | BL3: 28 | BM3: 2 | BN3: 3 | BO3: 4 | BP3: 5 | BQ3: 6 | BR3: 7 | BS3: 9 | BT3: 10 | BU3: 11 | BV3: 12 | BW3: 13 | BX3: 14 | BY3: 16 | BZ3: 17 | CA3: 18 | CB3: 19 | CC3: 20 | CD3: 21 | CE3: 23 | CF3: 24 | CG3: 25 | CH3: 26 | CI3: 27 | CJ3: 28 | CK3: 30 | CL3: 31 | CM3: 1 | CN3: 2 | CO3: 3 | CP3: 4 | CQ3: 6 | CR3: 7 | CS3: 8 | CT3: 9 | CU3: 10 | CV3: 11 | CW3: 13 | CX3: 14 | CY3: 15 | CZ3: 16 | DA3: 17 | DB3: 18 | DC3: 20 | DD3: 21 | DE3: 22 | DF3: 23 | DG3: 24 | DH3: 25 | DI3: 27 | DJ3: 28 | DK3: 29 | DL3: 30 | DM3: 1 | DN3: 2 | DO3: 4 | DP3: 5 | DQ3: 6 | DR3: 7 | DS3: 8 | DT3: 9 | DU3: 11 | DV3: 12 | DW3: 13 | DX3: 14 | DY3: 15 | DZ3: 16 | EA3: 18 | EB3: 19 | EC3: 20 | ED3: 21 | EE3: 22 | EF3: 23 | EG3: 25 | EH3: 26 | EI3: 27 | EJ3: 28 | EK3: 29 | EL3: 30 | EM3: 1 | EN3: 2 | EO3: 3 | EP3: 4 | EQ3: 5 | ER3: 6 | ES3: 8 | ET3: 9 | EU3: 10 | EV3: 11 | EW3: 12 | EX3: 13 | EY3: 15 | EZ3: 16 | FA3: 17 | FB3: 18 | FC3: 19 | FD3: 20 | FE3: 22 | FF3: 23 | FG3: 24 | FH3: 25 | FI3: 26 | FJ3: 27 | FK3: 29 | FL3: 30 | FM3: 1 | FN3: 2 | FO3: 3 | FP3: 4 | FQ3: 6 | FR3: 7 | FS3: 8 | FT3: 9 | FU3: 10 | FV3: 11 | FW3: 13 | FX3: 14 | FY3: 15 | FZ3: 16 | GA3: 17 | GB3: 18 | GC3: 20 | GD3: 21 | GE3: 22 | GF3: 23 | GG3: 24 | GH3: 25 | GI3: 27 | GJ3: 28 | GK3: 29 | GL3: 30 | GM3: 31 | GN3: 1 | GO3: 3 | GP3: 4 | GQ3: 5 | GR3: 6 | GS3: 7 | GT3: 8 | GU3: 10 | GV3: 11 | GW3: 12 | GX3: 13 | GY3: 14 | GZ3: 15 | HA3: 17 | HB3: 18 | HC3: 19 | HD3: 20 | HE3: 21 | HF3: 22 | HG3: 24 | HH3: 25 | HI3: 26 | HJ3: 27 | HK3: 28 | HL3: 29 | HM3: 31 | HN3: 1 | HO3: 2 | HP3: 3 | HQ3: 4 | HR3: 5 | HS3: 7 | HT3: 8 | HU3: 9 | HV3: 10 | HW3: 11 | HX3: 12 | HY3: 14 | HZ3: 15 | IA3: 16 | IB3: 17 | IC3: 18 | ID3: 19 | IE3: 21 | IF3: 22 | IG3: 23 | IH3: 24 | II3: 25 | IJ3: 26 | IK3: 28 | IL3: 29 | IM3: 30 | IN3: 1 | IO3: 2 | IP3: 3 | IQ3: 5 | IR3: 6 | IS3: 7 | IT3: 8 | IU3: 9 | IV3: 10 | IW3: 12 | IX3: 13 | IY3: 14 | IZ3: 15 | JA3: 16 | JB3: 17 | JC3: 19 | JD3: 20 | JE3: 21 | JF3: 22 | JG3: 23 | JH3: 24 | JI3: 26 | JJ3: 27 | JK3: 28 | JL3: 29 | JM3: 30 | JN3: 31 | JO3: 2 | JP3: 3 | JQ3: 4 | JR3: 5 | JS3: 6 | JT3: 7 | JU3: 9 | JV3: 10 | JW3: 11 | JX3: 12 | JY3: 13 | JZ3: 14 | KA3: 16 | KB3: 17 | KC3: 18 | KD3: 19 | KE3: 20 | KF3: 21 | KG3: 23 | KH3: 24 | KI3: 25 | KJ3: 26 | KK3: 27 | KL3: 28 | KM3: 30 | KN3: 1 | KO3: 2 | KP3: 3 | KQ3: 4 | KR3: 5 | KS3: 7 | KT3: 8 | KU3: 9 | KV3: 10 | KW3: 11 | KX3: 12 | KY3: 14 | KZ3: 15 | LA3: 16 | LB3: 17 | LC3: 18 | LD3: 19 | LE3: 21 | LF3: 22 | LG3: 23 | LH3: 24 | LI3: 25 | LJ3: 26 | LK3: 28 | LL3: 29 | LM3: 30 | LN3: 31
A4: 1 | B4: 1 | C4: Formulación y gestión de proyectos. | D4: 77000000 | E4: Presencial (50%) Virtual (50%) | F4: Cesar Augusto Prieto Cárdenas | I4: 100 | J4: 42 P: 17 V: 25 | K4: 46098 | L4: 46247 | M4: Martes y jueves P: 2 PM - 5 PM V: 2 PM - 4 PM | BZ4: 1 | CB4: 2 | CF4: 3 | CH4: 4 | CR4: 5 | CT4: 6 | CX4: 7 | CZ4: 8 | DD4: 9 | DF4: 10 | DJ4: 11 | DL4: 12 | DP4: 13 | DR4: 14 | DV4: 15 | DX4: 16 | EB4: 17 | ED4: 18 | EH4: 19 | EJ4: 20 | EN4: 21 | EP4: 22 | ET4: 23 | EV4: 24 | EZ4: 25 | FB4: 26 | FF4: 27 | FH4: 28 | FL4: 29 | FN4: 30 | FR4: 31 | FT4: 32 | FX4: 33 | FZ4: 34 | GD4: 35 | GF4: 36 | GJ4: 37 | GL4: 38 | GP4: 39 | GR4: 40 | GV4: 41 | GX4: 42
A5: 2 | B5: 1 | C5: Gestión del Conocimiento y Buenas Prácticas Institucionales | D5: 24640000 | E5: Presencial (50%) Virtual (50%) | F5: Bertha Viviana Ruales Guzmán | I5: 32 | J5: 13 P: 5 V: 8 | K5: 46237 | L5: 46335 | M5: Lunes o viernes P: 2 PM - 5 PM V: 2 PM - 4 PM | GO5: 1 | GU5: 2 | HE5: 3 | HG5: 4 | HM5: 5 | HS5: 6 | HY5: 7 | IK5: 8 | JA5: 9 | JC5: 10 | JI5: 11 | JS5: 12 | JU5: 13
A6: 3 | B6: 1 | C6: Gestión del Desempeño y Desarrollo de Competencias. | D6: 24640000 | E6: Presencial (50%) Virtual (50%) | F6: Diego Leon Reyes | I6: 32 | J6: 13 P: 5 V: 8 | K6: 46252 | L6: 46308 | M6: Martes y jueves P: 2 PM - 5 PM V: 2 PM - 4 PM | HB6: 1 | HD6: 2 | HH6: 3 | HJ6: 4 | HN6: 5 | HP6: 6 | HT6: 7 | HV6: 8 | HZ6: 9 | IB6: 10 | IL6: 11 | IN6: 12 | IX6: 13
A7: 4 | B7: 2 | C7: Gestión pública y transparencia | D7: 23040000 | E7: Presencial (20%) Virtual (80%) | F7: Docente principal: - Estefania Pisciotti Blanco Conferencistas invitados: - Paul Pulido Pachón | I7: 32 | J7: 15 P: 2 V: 13 | K7: 46162 | L7: 46220 | M7: Lunes, miércoles y viernes P: 9 AM - 12 PM V: 9 AM - 11 AM | EC7: 1 | EE7: 2 | EG7: 3 | EM7: 4 | EO7: 5 | EQ7: 6 | EW7: 7 | FA7: 8 | FE7: 9 | FI7: 10 | FO7: 11 | FQ7: 12 | FS7: 13 | FW7: 14 | GA7: 15
A8: 5 | B8: 2 | C8: Atención diferencial y comunicación efectiva | D8: 23040000 | E8: Presencial (20%) Virtual (80%) | F8: Olga Lucía Quintero Sierra | G8: =COUNTA(Tabla_AtnDiferencial[NOMBRE Y APELLIDOS]) -> 8 | H8: =COUNTIF(Tabla_AtnDiferencial[% ASISTENCIA],">=0,8") -> 7 | I8: 32 | J8: 15 P: 2 V: 13 | K8: 46097 | L8: 46150 | M8: Lunes, miércoles y viernes P: 9 AM - 12 PM V: 9 AM - 11 AM | BY8: 1 | CC8: 2 | CI8: 3 | CQ8: 4 | CS8: 5 | CU8: 6 | CW8: 7 | DA8: 8 | DC8: 9 | DE8: 10 | DG8: 11 | DI8: 12 | DO8: 13 | DQ8: 14 | DS8: 15
A9: 6 | B9: 2 | C9: Creación de Valor Público y Gestión para Resultados | D9: 28800000 | E9: Presencial (20%) Virtual (80%) | F9: Fredy Céspedes Villa | I9: 40 | J9: 19 P: 3 V: 16 | K9: 46230 | L9: 46279 | M9: Lunes, miércoles y viernes P: 9 AM - 12 PM V: 8 AM - 10 AM | GI9: 1 | GK9: 2 | GM9: 3 | GO9: 4 | GS9: 5 | GU9: 6 | GY9: 7 | HC9: 8 | HE9: 9 | HG9: 10 | HI9: 11 | HK9: 12 | HM9: 13 | HO9: 14 | HQ9: 15 | HS9: 16 | HU9: 17 | HW9: 18 | HY9: 19
A10: 7 | B10: 3 | C10: Gestión de bases de datos | D10: 77000000 | E10: Presencial (50%) Virtual (50%) | F10: Docente principal: - Robinson Andrés Jaque Pirabán Conferencistas invitados: - Jorge Eliecer Camargo Mendoza | I10: 100 | J10: 42 P: 17 V: 25 | K10: 46232 | L10: 46353 | M10: Lunes, miércoles y viernes P: 2 PM - 5 PM V: 2 PM - 4 AM | GK10: 1 | GM10: 2 | GO10: 3 | GQ10: 4 | GS10: 5 | GU10: 6 | GY10: 7 | HC10: 8 | HE10: 9 | HG10: 10 | HI10: 11 | HK10: 12 | HM10: 13 | HO10: 14 | HQ10: 15 | HS10: 16 | HU10: 17 | HW10: 18 | HY10: 19 | IA10: 20 | IC10: 21 | IK10: 22 | IM10: 23 | IO10: 24 | IY10: 25 | JA10: 26 | JC10: 27 | JE10: 28 | JG10: 29 | JI10: 30 | JK10: 31 | JM10: 32 | JQ10: 33 | JS10: 34 | JU10: 35 | JW10: 36 | JY10: 37 | KC10: 38 | KE10: 39 | KG10: 40 | KI10: 41 | KK10: 42
A11: 8 | B11: 3 | C11: Analítica de Datos e Inteligencia Artificial. | D11: 77000000 | E11: Presencial (50%) Virtual (50%) | F11: Docente principal: - Oscar Julián Perdomo Charry Conferencistas invitados: - Jorge Eliecer Camargo Mendoza - Felipe Restrepo Calle - Fabio Augusto González Osorio - Robinson Andrés Jaque Pirabán - Cesar Pedraza Bonilla | I11: 100 | J11: 42 P: 17 V: 25 | K11: 46092 | L11: 46230 | M11: Lunes, miércoles y viernes P: 1 PM - 4 PM V: 2 PM - 4 AM | BU11: 1 | BW11: 2 | BY11: 3 | CC11: 4 | CI11: 5 | CQ11: 6 | CS11: 7 | CU11: 8 | CW11: 9 | CY11: 10 | DA11: 11 | DC11: 12 | DE11: 13 | DG11: 14 | DI11: 15 | DK11: 16 | DO11: 17 | DQ11: 18 | DS11: 19 | DU11: 20 | DY11: 21 | EC11: 22 | EE11: 23 | EG11: 24 | EK11: 25 | EM11: 26 | EO11: 27 | EQ11: 28 | EU11: 29 | EW11: 30 | FA11: 31 | FE11: 32 | FG11: 33 | FI11: 34 | FM11: 35 | FO11: 36 | FQ11: 37 | FS11: 38 | FW11: 39 | GA11: 40 | GI11: 41
A12: 9 | B12: 3 | C12: Modelamiento y análisis de datos usando Power BI. | D12: 36960000 | E12: Presencial (50%) Virtual (50%) | F12: Edwar Leonardo Esteban Perez | I12: 48 | J12: 20 P: 8 V: 12 | K12: 46281 | L12: 46346 | M12: Lunes, miércoles y viernes P: 9 AM - 12 PM V: 10 AM - 12 PM | IA12: 1 | IC12: 2 | IK12: 3 | IM12: 4 | IO12: 5 | IY12: 6 | JA12: 7 | JC12: 8 | JE12: 9 | JG12: 10 | JI12: 11 | JK12: 12 | JM12: 13 | JQ12: 14 | JS12: 15 | JU12: 16 | JW12: 17 | JY12: 18 | KC12: 19 | KE12: 20
A13: 10 | B13: 4 | C13: Comunicación asertiva y Escucha Activa | D13: 23040000 | E13: Presencial (20%) Virtual (80%) | F13: Olga Lucía Quintero Sierra | G13: =COUNTA(Tabla_ComAsertiva[NOMBRE Y APELLIDOS]) -> 11 | H13: =COUNTIF(Tabla_ComAsertiva[% ASISTENCIA],">=0,8") -> 10 | I13: 32 | J13: 15 P: 2 V: 13 | K13: 46156 | L13: 46217 | M13: Martes y jueves P: 9 AM - 12 PM V: 10 AM - 12 PM | DX13: 1 | EB13: 2 | ED13: 3 | EH13: 4 | EJ13: 5 | EN13: 6 | EP13: 7 | EV13: 8 | EZ13: 9 | FF13: 10 | FH13: 11 | FN13: 12 | FR13: 13 | FT13: 14 | FX13: 15
A14: 11 | B14: 4 | C14: Gestión integral de riesgos | D14: 23040000 | E14: Presencial (20%) Virtual (80%) | F14: John Alejandro Cárdenas Morales | I14: 32 | J14: 15 P: 2 V: 13 | K14: 46219 | L14: 46282 | M14: Martes y jueves P: 9 AM - 12 PM V: 9 AM - 11 AM | FZ14: 1 | GF14: 2 | GJ14: 3 | GL14: 4 | GP14: 5 | GR14: 6 | GV14: 7 | GX14: 8 | HB14: 9 | HH14: 10 | HJ14: 11 | HN14: 12 | HT14: 13 | HV14: 14 | IB14: 15
A15: 12 | B15: 4 | C15: Pensamiento crítico para la toma de decisiones | D15: 23040000 | E15: Presencial (20%) Virtual (80%) | F15: William Angel Salazar Pulido | G15: =COUNTA(Tabla_PensamientoCrit[NOMBRE Y APELLIDOS]) -> 7 | H15: =COUNTIF(Tabla_PensamientoCrit[% ASISTENCIA],">=0,8") -> 6 | I15: 32 | J15: 15 P: 2 V: 13 | K15: 46098 | L15: 46154 | M15: Martes y jueves P: 9 AM - 12 PM V: 10 AM - 12 PM | BZ15: 1 | CB15: 2 | CF15: 3 | CH15: 4 | CR15: 5 | CT15: 6 | CX15: 7 | CZ15: 8 | DD15: 9 | DF15: 10 | DJ15: 11 | DL15: 12 | DP15: 13 | DR15: 14 | DV15: 15
A16: 13 | B16: N/A | C16: Reinducción e Inducción | D16: 35000000 | E16: Moodle | F16: N/A | I16: 8 | J16: N/A | K16: 46174 | L16: 46353 | M16: N/A
A17: 14 | B17: N/A | C17: Banco de conocimiento | D17: 35000000 | E17: Moodle | F17: N/A | I17: N/A | J17: N/A | K17: N/A | L17: N/A | M17: N/A
C18: Bolsa recursos | D18: 30000000

Sheet 1 - Formulación de proyectos
A1: UNIDAD DE EDUCACIÓN CONTINUA FACULTAD DE INGENIERÍA | AY1: VERSIÓN 1.0
AY3: PÁGINA 1 DE 1
A5: FACULTAD INGENIERÍA UNAL
A6: PROCESO: DESARROLLO DE LAS MODALIDADES DE EXTENSIÓN
A7: NOMBRE DEL CURSO, DIPLOMADO O PROYECTO
A8: DIPLOMADO "FORMULACIÓN DE PROYECTOS"
A9: NOMBRE DEL PROFESOR | E9: ='Formato Cronograma'!F4 -> Cesar Augusto Prieto Cárdenas | G9: N° S.PRESENCIALES(SP) | AA9: N° S.VIRTUALES SINCRÓNICAS(VS) | AW9: NOMBRE DEL MONITOR | BA9: DANIEL FELIPE CRUZ SAENZ
A10: FECHA DE INICIO | C10: ='Formato Cronograma'!K4 -> 46098 | D10: FECHA DE FIN | F10: ='Formato Cronograma'!L4 -> 46247 | G10: 16 | AA10: 26 | AW10: HORAS DEL DIPLOMADO | AY10: 100 | BA10: CÓDIGO HERMES
A11: INFORMACIÓN DEL ESTUDIANTE | G11: SESIONES | AW11: ASISTENCIA | BA11: NOTAS
A12: NO | B12: NOMBRE Y APELLIDOS | C12: DOCUMENTO | D12: TIPO DE VINCULACIÓN CON LA ENTIDAD | E12: ÁREA A LA QUE PERTENECE | F12: NOMBRE DEL CARGO | G12: 1 | H12: 2 | I12: 3 | J12: 4 | K12: 5 | L12: 6 | M12: 7 | N12: 8 | O12: 9 | P12: 10 | Q12: 11 | R12: 12 | S12: 13 | T12: 14 | U12: 15 | V12: 16 | W12: 17 | X12: 18 | Y12: 19 | Z12: 20 | AA12: 21 | AB12: 22 | AC12: 23 | AD12: 24 | AE12: 25 | AF12: 26 | AG12: 27 | AH12: 28 | AI12: 29 | AJ12: 30 | AK12: 31 | AL12: 32 | AM12: 33 | AN12: 34 | AO12: 35 | AP12: 36 | AQ12: 37 | AR12: 38 | AS12: 39 | AT12: 40 | AU12: 41 | AV12: 42 | AW12: HORAS ACUMULADAS | AX12: SESIONES ASISTIDAS | AY12: % ASISTENCIA | AZ12: ¿CUMPLE ASISTENCIA? | BA12: PRE | BB12: POST | BC12: FINAL | BD12: APROBACIÓN
A13: 1 | B13: Boris Fernando Rodríguez Rodríguez | C13: 79139672 | D13: Planta | E13: Subdirección De Liquidaciones Del Aseguramiento | F13: Gestor De Operaciones | G13: 3 | H13: 2 | I13: 2 | J13: 2 | K13: 2 | L13: 2 | M13: 3 | N13: 2 | O13: 3 | P13: 2 | Q13: 3 | R13: 2 | S13: 3 | T13: 2 | U13: 3 | V13: 2 | W13: 3 | X13: 2 | Y13: 2 | Z13: 2 | AA13: 3 | AB13: 2 | AC13: 3 | AD13: 2 | AE13: 3 | AF13: 2 | AG13: 3 | AH13: 2 | AI13: 3 | AJ13: 2 | AK13: 2 | AL13: 3 | AM13: 3 | AN13: 3 | AO13: 3 | AW13: =IF(B13<>"",SUM(G13:AV13),"") -> 86 | AX13: =IF(B13<>"",COUNTA(G13:AV13),"") -> 35 | AY13: =IF(B13<>"",SUM(G13:AV13)/100,"") -> 0.86 | AZ13: =IF(AY13="","",IF(AY13>=80%,"Certificado","No certificado")) -> Certificado | BD13: =IF(B13="","",IF(AND(AY13>=0.8,BC13>=3),"Aprobado","No aprobado")) -> No aprobado
A14: 2 | B14: Carlos Alberto Gómez Garay | C14: 79859706 | D14: Planta | E14: Dirección De Liquidaciones Y Garantías | F14: Gestor De Operaciones | G14: 3 | H14: 2 | I14: 2 | J14: 2 | L14: 2 | M14: 3 | N14: 2 | O14: 3 | P14: 2 | Q14: 3 | R14: 2 | S14: 3 | T14: 2 | U14: 3 | V14: 2 | W14: 3 | X14: 2 | Y14: 2 | Z14: 2 | AA14: 3 | AB14: 2 | AC14: 3 | AD14: 2 | AE14: 3 | AF14: 2 | AG14: 3 | AH14: 2 | AI14: 3 | AJ14: 2 | AK14: 2 | AL14: 3 | AM14: 3 | AN14: 3 | AW14: =IF(B14<>"",SUM(G14:AV14),"") -> 81 | AX14: =IF(B14<>"",COUNTA(G14:AV14),"") -> 35 | AY14: =IF(B14<>"",SUM(G14:AV14)/100,"") -> 0.81 | AZ14: =IF(AY14="","",IF(AY14>=80%,"Certificado","No certificado")) -> Certificado | BD14: =IF(B14="","",IF(AND(AY14>=0.8,BC14>=3),"Aprobado","No aprobado")) -> No aprobado
A15: 3 | B15: Carlos Andrés Ruiz Romero | C15: 86051326 | D15: Planta | E15: Dirección De Gestión De Tecnologías De Información Y Comunicaciones | F15: Gestor De Operaciones | AW15: =IF(B15<>"",SUM(G15:AV15),"") -> 0 | AX15: =IF(B15<>"",COUNTA(G15:AV15),"") -> 35 | AY15: =IF(B15<>"",SUM(G15:AV15)/100,"") -> 0 | AZ15: =IF(AY15="","",IF(AY15>=80%,"Certificado","No certificado")) -> No certificado | BD15: =IF(B15="","",IF(AND(AY15>=0.8,BC15>=3),"Aprobado","No aprobado")) -> No aprobado
A16: 4 | B16: José Leopoldo Bernal Bermúdez | C16: 79645745 | D16: Planta | E16: Dirección De Liquidaciones Y Garantías | F16: Gestor De Operaciones | G16: 3 | H16: 2 | I16: 2 | J16: 2 | K16: 2 | L16: 2 | M16: 3 | N16: 2 | O16: 3 | P16: 2 | Q16: 3 | R16: 2 | S16: 3 | T16: 2 | U16: 3 | V16: 2 | W16: 3 | X16: 2 | Y16: 2 | Z16: 2 | AB16: 2 | AC16: 3 | AD16: 2 | AE16: 3 | AF16: 2 | AG16: 3 | AH16: 2 | AI16: 3 | AJ16: 2 | AK16: 2 | AL16: 3 | AM16: 3 | AN16: 3 | AO16: 3 | AW16: =IF(B16<>"",SUM(G16:AV16),"") -> 83 | AX16: =IF(B16<>"",COUNTA(G16:AV16),"") -> 35 | AY16: =IF(B16<>"",SUM(G16:AV16)/100,"") -> 0.83 | AZ16: =IF(AY16="","",IF(AY16>=80%,"Certificado","No certificado")) -> Certificado | BD16: =IF(B16="","",IF(AND(AY16>=0.8,BC16>=3),"Aprobado","No aprobado")) -> No aprobado
A17: 5 | B17: Julio Cesar Ospina Marmolejo | C17: 79359722 | D17: Planta | E17: Dirección De Otras Prestaciones | F17: Gestor De Operaciones | G17: 3 | H17: 2 | I17: 2 | K17: 2 | L17: 2 | M17: 3 | O17: 3 | P17: 2 | Q17: 3 | R17: 2 | S17: 3 | T17: 2 | U17: 3 | V17: 2 | W17: 3 | X17: 2 | Y17: 2 | Z17: 2 | AA17: 3 | AB17: 2 | AC17: 3 | AD17: 2 | AE17: 3 | AF17: 2 | AG17: 3 | AH17: 2 | AJ17: 2 | AK17: 2 | AL17: 3 | AM17: 3 | AN17: 3 | AW17: =IF(B17<>"",SUM(G17:AV17),"") -> 76 | AX17: =IF(B17<>"",COUNTA(G17:AV17),"") -> 35 | AY17: =IF(B17<>"",SUM(G17:AV17)/100,"") -> 0.76 | AZ17: =IF(AY17="","",IF(AY17>=80%,"Certificado","No certificado")) -> No certificado | BD17: =IF(B17="","",IF(AND(AY17>=0.8,BC17>=3),"Aprobado","No aprobado")) -> No aprobado
A18: 6 | B18: Oscar Mauricio Vanegas Vargas | C18: 80215478 | D18: Planta | E18: Dirección De Gestión De Tecnologías De Información Y Comunicaciones | F18: Gestor De Operaciones | G18: 3 | H18: 2 | I18: 2 | J18: 2 | K18: 2 | L18: 2 | M18: 3 | N18: 2 | O18: 3 | P18: 2 | Q18: 3 | R18: 2 | S18: 3 | T18: 2 | U18: 3 | V18: 2 | W18: 3 | X18: 2 | Y18: 2 | Z18: 2 | AA18: 3 | AB18: 2 | AC18: 3 | AD18: 2 | AE18: 3 | AF18: 2 | AG18: 3 | AH18: 2 | AI18: 3 | AJ18: 2 | AK18: 2 | AL18: 3 | AM18: 3 | AN18: 3 | AO18: 3 | AW18: =IF(B18<>"",SUM(G18:AV18),"") -> 86 | AX18: =IF(B18<>"",COUNTA(G18:AV18),"") -> 35 | AY18: =IF(B18<>"",SUM(G18:AV18)/100,"") -> 0.86 | AZ18: =IF(AY18="","",IF(AY18>=80%,"Certificado","No certificado")) -> Certificado | BD18: =IF(B18="","",IF(AND(AY18>=0.8,BC18>=3),"Aprobado","No aprobado")) -> No aprobado
A19: Observaciones:

Sheet 2 - Gestión del conocimiento
A1: UNIDAD DE EDUCACIÓN CONTINUA FACULTAD DE INGENIERÍA | V1: VERSIÓN 1.0
V3: PÁGINA 1 DE 1
A5: FACULTAD INGENIERÍA UNAL
A6: PROCESO: DESARROLLO DE LAS MODALIDADES DE EXTENSIÓN
A7: NOMBRE DEL CURSO, DIPLOMADO O PROYECTO
A8: CURSO "XX"
A9: NOMBRE DEL PROFESOR | E9: ='Formato Cronograma'!F5 -> Bertha Viviana Ruales Guzmán | G9: N° S.PRESENCIALES(SP) | O9: N° S.VIRTUALES SINCRÓNICAS(VS) | T9: NOMBRE DEL MONITOR | X9: DANIEL FELIPE CRUZ SAENZ
A10: FECHA DE INICIO | C10: ='Formato Cronograma'!K5 -> 46237 | D10: FECHA DE FIN | F10: ='Formato Cronograma'!L5 -> 46335 | G10: 5 | O10: 8 | T10: HORAS DEL CURSO | V10: 32 | X10: CÓDIGO HERMES
A11: INFORMACIÓN DEL ESTUDIANTE | G11: SESIONES | T11: ASISTENCIA | X11: NOTAS
A12: NO | B12: NOMBRE Y APELLIDOS | C12: DOCUMENTO | D12: TIPO DE VINCULACIÓN CON LA ENTIDAD | E12: ÁREA A LA QUE PERTENECE | F12: NOMBRE DEL CARGO | G12: 1 | H12: 2 | I12: 3 | J12: 4 | K12: 5 | L12: 6 | M12: 7 | N12: 8 | O12: 9 | P12: 10 | Q12: 11 | R12: 12 | S12: 13 | T12: HORAS ACUMULADAS | U12: SESIONES ASISTIDAS | V12: % ASISTENCIA | W12: ¿CUMPLE ASISTENCIA? | X12: PRE | Y12: POST | Z12: FINAL | AA12: APROBACIÓN
A13: 1 | B13: Edilberto Zamora Alvarado | C13: 19259792 | D13: Planta | E13: =_xlfn.XLOOKUP(C13,[1]Hoja1!$B:$B,[1]Hoja1!$G:$G) -> DIRECCIÓN DE GESTIÓN DE TECNOLOGÍAS DE INFORMACIÓN Y COMUNICACIONES | F13: =_xlfn.XLOOKUP(C13,[1]Hoja1!$B:$B,[1]Hoja1!$F:$F) -> GESTOR DE OPERACIONES | T13: =IF(B13<>"",SUM(G13:S13),"") -> 0 | U13: =IF(B13<>"",COUNTA(G13:S13),"") -> 0 | V13: =IF(B13<>"",SUM(G13:S13)/40,"") -> 0 | W13: =IF(V13="","",IF(V13>=80%,"Certificado","No certificado")) -> No certificado | AA13: =IF(B13="","",IF(AND(V13>=0.8,Z13>=3),"Aprobado","No aprobado")) -> No aprobado
A14: 2 | B14: Francy Abril Morales | C14: 52498179 | D14: Planta | E14: =_xlfn.XLOOKUP(C14,[1]Hoja1!$B:$B,[1]Hoja1!$G:$G) -> DIRECCIÓN ADMINISTRATIVA Y FINANCIERA | F14: =_xlfn.XLOOKUP(C14,[1]Hoja1!$B:$B,[1]Hoja1!$F:$F) -> GESTOR DE OPERACIONES | T14: =IF(B14<>"",SUM(G14:S14),"") -> 0 | U14: =IF(B14<>"",COUNTA(G14:S14),"") -> 0 | V14: =IF(B14<>"",SUM(G14:S14)/40,"") -> 0 | W14: =IF(V14="","",IF(V14>=80%,"Certificado","No certificado")) -> No certificado | AA14: =IF(B14="","",IF(AND(V14>=0.8,Z14>=3),"Aprobado","No aprobado")) -> No aprobado
A15: 3 | B15: Juan Carlos Giron Sanabria | C15: 14139437 | D15: Planta | E15: =_xlfn.XLOOKUP(C15,[1]Hoja1!$B:$B,[1]Hoja1!$G:$G) -> SUBDIRECCIÓN DE LIQUIDACIONES DEL ASEGURAMIENTO | F15: =_xlfn.XLOOKUP(C15,[1]Hoja1!$B:$B,[1]Hoja1!$F:$F) -> GESTOR DE OPERACIONES | T15: =IF(B15<>"",SUM(G15:S15),"") -> 0 | U15: =IF(B15<>"",COUNTA(G15:S15),"") -> 0 | V15: =IF(B15<>"",SUM(G15:S15)/40,"") -> 0 | W15: =IF(V15="","",IF(V15>=80%,"Certificado","No certificado")) -> No certificado | AA15: =IF(B15="","",IF(AND(V15>=0.8,Z15>=3),"Aprobado","No aprobado")) -> No aprobado
A16: 4 | B16: Luisa Fernanda Diaz Gonzalez | C16: 1032399404 | D16: Planta | E16: =_xlfn.XLOOKUP(C16,[1]Hoja1!$B:$B,[1]Hoja1!$G:$G) -> DIRECCIÓN DE OTRAS PRESTACIONES | F16: =_xlfn.XLOOKUP(C16,[1]Hoja1!$B:$B,[1]Hoja1!$F:$F) -> GESTOR DE OPERACIONES | T16: =IF(B16<>"",SUM(G16:S16),"") -> 0 | U16: =IF(B16<>"",COUNTA(G16:S16),"") -> 0 | V16: =IF(B16<>"",SUM(G16:S16)/40,"") -> 0 | W16: =IF(V16="","",IF(V16>=80%,"Certificado","No certificado")) -> No certificado | AA16: =IF(B16="","",IF(AND(V16>=0.8,Z16>=3),"Aprobado","No aprobado")) -> No aprobado
A17: 5 | B17: Maria Fernanda Fragozo Alvarez | C17: 1121332079 | D17: Planta | E17: =_xlfn.XLOOKUP(C17,[1]Hoja1!$B:$B,[1]Hoja1!$G:$G) -> OFICINA DE CONTROL INTERNO | F17: =_xlfn.XLOOKUP(C17,[1]Hoja1!$B:$B,[1]Hoja1!$F:$F) -> GESTOR DE OPERACIONES | T17: =IF(B17<>"",SUM(G17:S17),"") -> 0 | U17: =IF(B17<>"",COUNTA(G17:S17),"") -> 0 | V17: =IF(B17<>"",SUM(G17:S17)/40,"") -> 0 | W17: =IF(V17="","",IF(V17>=80%,"Certificado","No certificado")) -> No certificado | AA17: =IF(B17="","",IF(AND(V17>=0.8,Z17>=3),"Aprobado","No aprobado")) -> No aprobado
A18: 6 | B18: Paola Andrea Cespedes Forero | C18: 52536438 | D18: Planta | E18: =_xlfn.XLOOKUP(C18,[1]Hoja1!$B:$B,[1]Hoja1!$G:$G) -> DIRECCIÓN DE OTRAS PRESTACIONES | F18: =_xlfn.XLOOKUP(C18,[1]Hoja1!$B:$B,[1]Hoja1!$F:$F) -> GESTOR DE OPERACIONES | T18: =IF(B18<>"",SUM(G18:S18),"") -> 0 | U18: =IF(B18<>"",COUNTA(G18:S18),"") -> 0 | V18: =IF(B18<>"",SUM(G18:S18)/40,"") -> 0 | W18: =IF(V18="","",IF(V18>=80%,"Certificado","No certificado")) -> No certificado | AA18: =IF(B18="","",IF(AND(V18>=0.8,Z18>=3),"Aprobado","No aprobado")) -> No aprobado
A19: 7 | B19: Teodolinda Sanchez Delgado | C19: 28977244 | D19: Planta | E19: =_xlfn.XLOOKUP(C19,[1]Hoja1!$B:$B,[1]Hoja1!$G:$G) -> OFICINA DE CONTROL INTERNO | F19: =_xlfn.XLOOKUP(C19,[1]Hoja1!$B:$B,[1]Hoja1!$F:$F) -> GESTOR DE OPERACIONES | T19: =IF(B19<>"",SUM(G19:S19),"") -> 0 | U19: =IF(B19<>"",COUNTA(G19:S19),"") -> 0 | V19: =IF(B19<>"",SUM(G19:S19)/40,"") -> 0 | W19: =IF(V19="","",IF(V19>=80%,"Certificado","No certificado")) -> No certificado | AA19: =IF(B19="","",IF(AND(V19>=0.8,Z19>=3),"Aprobado","No aprobado")) -> No aprobado
A20: 8 | B20: Wilmer Garcia Londoño | C20: 80152956 | D20: Planta | E20: =_xlfn.XLOOKUP(C20,[1]Hoja1!$B:$B,[1]Hoja1!$G:$G) -> DIRECCIÓN DE GESTIÓN DE TECNOLOGÍAS DE INFORMACIÓN Y COMUNICACIONES | F20: =_xlfn.XLOOKUP(C20,[1]Hoja1!$B:$B,[1]Hoja1!$F:$F) -> GESTOR DE OPERACIONES | T20: =IF(B20<>"",SUM(G20:S20),"") -> 0 | U20: =IF(B20<>"",COUNTA(G20:S20),"") -> 0 | V20: =IF(B20<>"",SUM(G20:S20)/40,"") -> 0 | W20: =IF(V20="","",IF(V20>=80%,"Certificado","No certificado")) -> No certificado | AA20: =IF(B20="","",IF(AND(V20>=0.8,Z20>=3),"Aprobado","No aprobado")) -> No aprobado
A21: 9 | B21: Yerly Alejandra Niño Castillo | C21: 52353064 | D21: Planta | E21: =_xlfn.XLOOKUP(C21,[1]Hoja1!$B:$B,[1]Hoja1!$G:$G) -> SUBDIRECCIÓN DE LIQUIDACIONES DEL ASEGURAMIENTO | F21: =_xlfn.XLOOKUP(C21,[1]Hoja1!$B:$B,[1]Hoja1!$F:$F) -> GESTOR DE OPERACIONES | T21: =IF(B21<>"",SUM(G21:S21),"") -> 0 | U21: =IF(B21<>"",COUNTA(G21:S21),"") -> 0 | V21: =IF(B21<>"",SUM(G21:S21)/40,"") -> 0 | W21: =IF(V21="","",IF(V21>=80%,"Certificado","No certificado")) -> No certificado | AA21: =IF(B21="","",IF(AND(V21>=0.8,Z21>=3),"Aprobado","No aprobado")) -> No aprobado
A22: Observaciones:

Sheet 3 - Gestión del desempeño
A1: UNIDAD DE EDUCACIÓN CONTINUA FACULTAD DE INGENIERÍA | V1: VERSIÓN 1.0
V3: PÁGINA 1 DE 1
A5: FACULTAD INGENIERÍA UNAL
A6: PROCESO: DESARROLLO DE LAS MODALIDADES DE EXTENSIÓN
A7: NOMBRE DEL CURSO, DIPLOMADO O PROYECTO
A8: CURSO "XX"
A9: NOMBRE DEL PROFESOR | E9: ='Formato Cronograma'!F6 -> Diego Leon Reyes | G9: N° S.PRESENCIALES(SP) | O9: N° S.VIRTUALES SINCRÓNICAS(VS) | T9: NOMBRE DEL MONITOR | X9: DANIEL FELIPE CRUZ SAENZ
A10: FECHA DE INICIO | C10: ='Formato Cronograma'!K6 -> 46252 | D10: FECHA DE FIN | F10: ='Formato Cronograma'!L6 -> 46308 | G10: 5 | O10: 8 | T10: HORAS DEL CURSO | V10: 32 | X10: CÓDIGO HERMES
A11: INFORMACIÓN DEL ESTUDIANTE | G11: SESIONES | T11: ASISTENCIA | X11: NOTAS
A12: NO | B12: NOMBRE Y APELLIDOS | C12: DOCUMENTO | D12: TIPO DE VINCULACIÓN CON LA ENTIDAD | E12: ÁREA A LA QUE PERTENECE | F12: NOMBRE DEL CARGO | G12: 1 | H12: 2 | I12: 3 | J12: 4 | K12: 5 | L12: 6 | M12: 7 | N12: 8 | O12: 9 | P12: 10 | Q12: 11 | R12: 12 | S12: 13 | T12: HORAS ACUMULADAS | U12: SESIONES ASISTIDAS | V12: % ASISTENCIA | W12: ¿CUMPLE ASISTENCIA? | X12: PRE | Y12: POST | Z12: FINAL | AA12: APROBACIÓN
A13: 1 | T13: =IF(B13<>"",SUM(G13:S13),"") | U13: =IF(B13<>"",COUNTA(G13:S13),"") | V13: =IF(B13<>"",SUM(G13:S13)/40,"") | W13: =IF(V13="","",IF(V13>=80%,"Certificado","No certificado")) | AA13: =IF(B13="","",IF(AND(V13>=0.8,Z13>=3),"Aprobado","No aprobado"))
A14: 2 | T14: =IF(B14<>"",SUM(G14:S14),"") | U14: =IF(B14<>"",COUNTA(G14:S14),"") | V14: =IF(B14<>"",SUM(G14:S14)/40,"") | W14: =IF(V14="","",IF(V14>=80%,"Certificado","No certificado")) | AA14: =IF(B14="","",IF(AND(V14>=0.8,Z14>=3),"Aprobado","No aprobado"))
A15: 3 | T15: =IF(B15<>"",SUM(G15:S15),"") | U15: =IF(B15<>"",COUNTA(G15:S15),"") | V15: =IF(B15<>"",SUM(G15:S15)/40,"") | W15: =IF(V15="","",IF(V15>=80%,"Certificado","No certificado")) | AA15: =IF(B15="","",IF(AND(V15>=0.8,Z15>=3),"Aprobado","No aprobado"))
A16: 4 | T16: =IF(B16<>"",SUM(G16:S16),"") | U16: =IF(B16<>"",COUNTA(G16:S16),"") | V16: =IF(B16<>"",SUM(G16:S16)/40,"") | W16: =IF(V16="","",IF(V16>=80%,"Certificado","No certificado")) | AA16: =IF(B16="","",IF(AND(V16>=0.8,Z16>=3),"Aprobado","No aprobado"))
A17: 5 | T17: =IF(B17<>"",SUM(G17:S17),"") | U17: =IF(B17<>"",COUNTA(G17:S17),"") | V17: =IF(B17<>"",SUM(G17:S17)/40,"") | W17: =IF(V17="","",IF(V17>=80%,"Certificado","No certificado")) | AA17: =IF(B17="","",IF(AND(V17>=0.8,Z17>=3),"Aprobado","No aprobado"))
A18: 6 | T18: =IF(B18<>"",SUM(G18:S18),"") | U18: =IF(B18<>"",COUNTA(G18:S18),"") | V18: =IF(B18<>"",SUM(G18:S18)/40,"") | W18: =IF(V18="","",IF(V18>=80%,"Certificado","No certificado")) | AA18: =IF(B18="","",IF(AND(V18>=0.8,Z18>=3),"Aprobado","No aprobado"))
A19: 7 | T19: =IF(B19<>"",SUM(G19:S19),"") | U19: =IF(B19<>"",COUNTA(G19:S19),"") | V19: =IF(B19<>"",SUM(G19:S19)/40,"") | W19: =IF(V19="","",IF(V19>=80%,"Certificado","No certificado")) | AA19: =IF(B19="","",IF(AND(V19>=0.8,Z19>=3),"Aprobado","No aprobado"))
A20: 8 | T20: =IF(B20<>"",SUM(G20:S20),"") | U20: =IF(B20<>"",COUNTA(G20:S20),"") | V20: =IF(B20<>"",SUM(G20:S20)/40,"") | W20: =IF(V20="","",IF(V20>=80%,"Certificado","No certificado")) | AA20: =IF(B20="","",IF(AND(V20>=0.8,Z20>=3),"Aprobado","No aprobado"))
A21: 9 | T21: =IF(B21<>"",SUM(G21:S21),"") | U21: =IF(B21<>"",COUNTA(G21:S21),"") | V21: =IF(B21<>"",SUM(G21:S21)/40,"") | W21: =IF(V21="","",IF(V21>=80%,"Certificado","No certificado")) | AA21: =IF(B21="","",IF(AND(V21>=0.8,Z21>=3),"Aprobado","No aprobado"))
A22: 10 | T22: =IF(B22<>"",SUM(G22:S22),"") | U22: =IF(B22<>"",COUNTA(G22:S22),"") | V22: =IF(B22<>"",SUM(G22:S22)/40,"") | W22: =IF(V22="","",IF(V22>=80%,"Certificado","No certificado")) | AA22: =IF(B22="","",IF(AND(V22>=0.8,Z22>=3),"Aprobado","No aprobado"))
A23: 11 | T23: =IF(B23<>"",SUM(G23:S23),"") | U23: =IF(B23<>"",COUNTA(G23:S23),"") | V23: =IF(B23<>"",SUM(G23:S23)/40,"") | W23: =IF(V23="","",IF(V23>=80%,"Certificado","No certificado")) | AA23: =IF(B23="","",IF(AND(V23>=0.8,Z23>=3),"Aprobado","No aprobado"))
A24: 12 | T24: =IF(B24<>"",SUM(G24:S24),"") | U24: =IF(B24<>"",COUNTA(G24:S24),"") | V24: =IF(B24<>"",SUM(G24:S24)/40,"") | W24: =IF(V24="","",IF(V24>=80%,"Certificado","No certificado")) | AA24: =IF(B24="","",IF(AND(V24>=0.8,Z24>=3),"Aprobado","No aprobado"))
... A28: 16 | T28: =IF(B28<>"",SUM(G28:S28),"") | U28: =IF(B28<>"",COUNTA(G28:S28),"") | V28: =IF(B28<>"",SUM(G28:S28)/40,"") | W28: =IF(V28="","",IF(V28>=80%,"Certificado","No certificado")) | AA28: =IF(B28="","",IF(AND(V28>=0.8,Z28>=3),"Aprobado","No aprobado"))
A29: Observaciones:

Sheet 4 - Gestión pública
A1: UNIDAD DE EDUCACIÓN CONTINUA FACULTAD DE INGENIERÍA | X1: VERSIÓN 1.0 | AD1: AD13
AD2: 4
X3: PÁGINA 1 DE 1 | AD3: 5
A5: FACULTAD INGENIERÍA UNAL
A6: PROCESO: DESARROLLO DE LAS MODALIDADES DE EXTENSIÓN
A7: NOMBRE DEL CURSO, DIPLOMADO O PROYECTO
A8: CURSO "Gestión Pública y Transparencia"
A9: NOMBRE DEL PROFESOR | E9: ='Formato Cronograma'!F7 -> Docente principal: - Estefania Pisciotti Blanco Conferencistas invitados: - Paul Pulido Pachón | G9: N° S.PRESENCIALES(SP) | O9: N° S.VIRTUALES SINCRÓNICAS(VS) | V9: NOMBRE DEL MONITOR | Z9: DANIEL FELIPE CRUZ SAENZ
A10: FECHA DE INICIO | C10: ='Formato Cronograma'!K7 -> 46162 | D10: FECHA DE FIN | F10: ='Formato Cronograma'!L7 -> 46220 | G10: 2 | O10: 13 | V10: HORAS DEL CURSO | X10: 32 | Z10: CÓDIGO HERMES | AA10: 62738 | AD10: ENCUESTA
A11: INFORMACIÓN DEL ESTUDIANTE | G11: SESIONES | V11: ASISTENCIA | Z11: NOTAS | AD11: ENCUESTA - DOCENTE PRINCIPAL (ESTEFANÍA PISCIOTTI BLANCO) | AJ11: ENCUESTA - CONFERENCISTA INVITADO (PAUL PULIDO PACHÓN) | AP11: ENCUESTA - MONITOR | AS11: ENCUESTA - LOGÍSTICA | BC11: ENCUESTA - PREGUNTAS ABIERTAS | BH11: TOTAL
A12: NO | B12: NOMBRE Y APELLIDOS | C12: DOCUMENTO | D12: TIPO DE VINCULACIÓN CON LA ENTIDAD | E12: ÁREA A LA QUE PERTENECE | F12: NOMBRE DEL CARGO | G12: 1 | H12: 2 | I12: 3 | J12: 4 | K12: 5 | L12: 6 | M12: 7 | N12: 8 | O12: 9 | P12: 10 | Q12: 11 | R12: 12 | S12: 13 | T12: 14 | U12: 15 | V12: HORAS ACUMULADAS | W12: SESIONES ASISTIDAS | X12: % ASISTENCIA | Y12: ¿CUMPLE ASISTENCIA? | Z12: PRE | AA12: POST | AB12: FINAL | AC12: APROBACIÓN | AD12: 1,1 El cumplimiento de los objetivos y desarrollo del contenido de la actividad fue | AE12: 1,2 Actualización en el área | AF12: 1,3 Capacidad para comunicar ideas | AG12: 1,4 Pertinencia de la metodología empleada | AH12: 1,5 Cumplimiento de los horarios previstos en el cronograma de la actividad | AI12: 1,6 Conocimiento y dominio de los temas | AJ12: 1,1 El cumplimiento de los objetivos y desarrollo del contenido de la actividad fue | AK12: 1,2 Actualización en el área | AL12: 1,3 Capacidad para comunicar ideas | AM12: 1,4 Pertinencia de la metodología empleada | AN12: 1,5 Cumplimiento de los horarios previstos en el cronograma de la actividad | AO12: 1,6 Conocimiento y dominio de los temas | AP12: 2,1 Apoyo al conferencista y asistentes en las tareas previstas en la actividad | AQ12: 2,2 Acompañamiento en cada una de las sesiones de la actividad | AR12: 2,3 Disposición y actitud frente a los asistentes | AS12: 3,1 Contenido del material suministrado | AT12: 3,2 Presentación del material suministrado | AU12: 3,3 Atención de refrigerios | AV12: 3,4 Instalaciones Físicas | AW12: 3,5 Ayudas audiovisuales | AX12: 3,6 Atención en el proceso de inscripción | AY12: 3,7 Disponibilidad del aula virtual | AZ12: 3,8 Contacto con el docente | BA12: 3,9 Pertinencia del material dispuesto en la plataforma | BB12: 3,10 Manejo de las herramientas digitales | BC12: 4,1 ¿Qué temas considera necesarios profundizar en este actividad? | BD12: 4,2 ¿Qué recomendaciones haría para mejorar las actividades? | BE12: 4,3 ¿En qué áreas desearía obtener información y/o actualización a través de las actividades de Educación Continua y Permanente? | BF12: 4,4 ¿Asistiría a otra actividad programada por nosotros? | BG12: 4,5 ¿La actividad fue satisfactoria? | BH12: Promedio
A13: 1 | B13: Ana Milena Escobar Rincón | C13: 63532359 | D13: Planta | E13: Dirección Administrativa y Financiera | F13: =_xlfn.XLOOKUP(C13,[1]Hoja1!$B:$B,[1]Hoja1!$F:$F) -> GESTOR DE OPERACIONES | G13: 3 | H13: 2 | I13: 2 | J13: 2 | K13: 2 | M13: 2 | N13: 2 | O13: 2 | R13: 2 | S13: 2 | T13: 2 | U13: 3 | V13: =IF(B13<>"",SUM(G13:U13),"") -> 26 | W13: =IF(B13<>"",COUNTA(G13:U13),"") -> 15 | X13: =IF(B13<>"",SUM(G13:U13)/32,"") -> 0.8125 | Y13: =IF(X13="","",IF(X13>=80%,"Certificado","No certificado")) -> Certificado | Z13: NP | AA13: 4 | AB13: 4 | AC13: =IF(B13="","",IF(AND(X13>=0.8,AB13>=3),"Aprobado","No aprobado")) -> Aprobado | AD13: 4 | AE13: 5 | AF13: 5 | AG13: 5 | AH13: 5 | AI13: 4 | AJ13: 4 | AK13: 4 | AL13: 4 | AM13: 4 | AN13: 4 | AO13: 4 | AP13: 5 | AQ13: 5 | AR13: 5 | AS13: 4 | AT13: 4 | AU13: 5 | AV13: 4 | AW13: 4 | AX13: 5 | AY13: 5 | AZ13: 5 | BA13: 5 | BB13: 5 | BC13: * | BD13: Que no sea en instalaciones de la entidad. | BE13: * | BF13: SI | BG13: 4 | BH13: =AVERAGE(AD13:BG13) -> 4.5
A14: 2 | B14: Andrea Paola Medina Salazar | C14: 1016051844 | D14: Planta | E14: Dirección Administrativa y Financiera | F14: =_xlfn.XLOOKUP(C14,[1]Hoja1!$B:$B,[1]Hoja1!$F:$F) -> GESTOR DE OPERACIONES | G14: 3 | H14: 2 | I14: 2 | J14: 2 | K14: 2 | L14: 2 | N14: 2 | O14: 2 | P14: 2 | Q14: 2 | R14: 2 | S14: 2 | T14: 2 | U14: 3 | V14: =IF(B14<>"",SUM(G14:U14),"") -> 30 | W14: =IF(B14<>"",COUNTA(G14:U14),"") -> 15 | X14: =IF(B14<>"",SUM(G14:U14)/32,"") -> 0.9375 | Y14: =IF(X14="","",IF(X14>=80%,"Certificado","No certificado")) -> Certificado | Z14: 4 | AA14: NP | AB14: 4 | AC14: =IF(B14="","",IF(AND(X14>=0.8,AB14>=3),"Aprobado","No aprobado")) -> Aprobado | AD14: 4 | AE14: 5 | AF14: 5 | AG14: 5 | AH14: 5 | AI14: 4 | AJ14: 4 | AK14: 4 | AL14: 4 | AM14: 4 | AN14: 4 | AO14: 4 | AP14: 5 | AQ14: 5 | AR14: 5 | AS14: 5 | AT14: 5 | AU14: 5 | AV14: 5 | AW14: 5 | AX14: 5 | AY14: 5 | AZ14: 5 | BA14: 5 | BB14: 5 | BC14: estuvo muy completo el curso y los temas manejados | BD14: por el momento todo fue de mi agrado y el curso muy completo | BE14: leyes actualizadas que puedan aplicar a la entidad | BF14: SI | BG14: 5 | BH14: =AVERAGE(AD14:BG14) -> 4.6923077
A15: 3 | B15: Angie Carolina Velasco Martínez | C15: 52761826 | D15: Planta | E15: Dirección Administrativa y Financiera | F15: =_xlfn.XLOOKUP(C15,[1]Hoja1!$B:$B,[1]Hoja1!$F:$F) -> GESTOR DE OPERACIONES | G15: 3 | I15: 2 | J15: 2 | K15: 2 | M15: 2 | N15: 2 | O15: 2 | P15: 2 | Q15: 2 | S15: 2 | T15: 2 | U15: 3 | V15: =IF(B15<>"",SUM(G15:U15),"") -> 26 | W15: =IF(B15<>"",COUNTA(G15:U15),"") -> 15 | X15: =IF(B15<>"",SUM(G15:U15)/32,"") -> 0.8125 | Y15: =IF(X15="","",IF(X15>=80%,"Certificado","No certificado")) -> Certificado | Z15: 4 | AA15: NP | AB15: 4 | AC15: =IF(B15="","",IF(AND(X15>=0.8,AB15>=3),"Aprobado","No aprobado")) -> Aprobado
A16: 4 | B16: Camilo Alberto Alfaro Jiménez | C16: 1020740232 | D16: Planta | E16: Dirección de Otras Prestaciones | F16: =_xlfn.XLOOKUP(C16,[1]Hoja1!$B:$B,[1]Hoja1!$F:$F) -> GESTOR DE OPERACIONES | G16: 3 | H16: 2 | I16: 2 | J16: 2 | K16: 2 | L16: 2 | N16: 2 | O16: 2 | R16: 2 | S16: 2 | T16: 2 | U16: 3 | V16: =IF(B16<>"",SUM(G16:U16),"") -> 26 | W16: =IF(B16<>"",COUNTA(G16:U16),"") -> 15 | X16: =IF(B16<>"",SUM(G16:U16)/32,"") -> 0.8125 | Y16: =IF(X16="","",IF(X16>=80%,"Certificado","No certificado")) -> Certificado | Z16: 4 | AA16: NP | AB16: 4 | AC16: =IF(B16="","",IF(AND(X16>=0.8,AB16>=3),"Aprobado","No aprobado")) -> Aprobado | AD16: 5 | AE16: 5 | AF16: 5 | AG16: 5 | AH16: 5 | AI16: 5 | AJ16: 5 | AK16: 5 | AL16: 5 | AM16: 5 | AN16: 5 | AO16: 5 | AP16: 5 | AQ16: 5 | AR16: 5 | AS16: 5 | AT16: 4 | AU16: 5 | AV16: 5 | AW16: 5 | AX16: 4 | AY16: 4 | AZ16: 4 | BA16: 4 | BB16: 5 | BC16: N/A - Fue muy amplia y asertiva | BD16: más clases para tener un poco mas de espacio en el estudio de cada tema | BE16: estructura del estado | BF16: SI | BG16: 5 | BH16: =AVERAGE(AD16:BG16) -> 4.8076923
A17: 5 | B17: Diana Esperanza Torres Rodríguez | C17: 52758406 | D17: Planta | E17: Oficina Asesora de Planeación y Control de Riesgos | F17: =_xlfn.XLOOKUP(C17,[1]Hoja1!$B:$B,[1]Hoja1!$F:$F) -> GESTOR DE OPERACIONES | H17: 2 | I17: 2 | K17: 2 | M17: 2 | P17: 2 | Q17: 2 | R17: 2 | S17: 2 | T17: 2 | U17: 3 | V17: =IF(B17<>"",SUM(G17:U17),"") -> 21 | W17: =IF(B17<>"",COUNTA(G17:U17),"") -> 15 | X17: =IF(B17<>"",SUM(G17:U17)/32,"") -> 0.65625 | Y17: =IF(X17="","",IF(X17>=80%,"Certificado","No certificado")) -> No certificado | Z17: 4 | AA17: NP | AB17: 3 | AC17: =IF(B17="","",IF(AND(X17>=0.8,AB17>=3),"Aprobado","No aprobado")) -> No aprobado
A18: 6 | B18: Edinson Mauricio Hernández Manrique | C18: 13928254 | D18: Planta | E18: Dirección de Otras Prestaciones | F18: =_xlfn.XLOOKUP(C18,[1]Hoja1!$B:$B,[1]Hoja1!$F:$F) -> GESTOR | G18: 3 | H18: 2 | I18: 2 | J18: 2 | K18: 2 | M18: 2 | O18: 2 | P18: 2 | Q18: 2 | R18: 2 | S18: 2 | T18: 2 | U18: 3 | V18: =IF(B18<>"",SUM(G18:U18),"") -> 28 | W18: =IF(B18<>"",COUNTA(G18:U18),"") -> 15 | X18: =IF(B18<>"",SUM(G18:U18)/32,"") -> 0.875 | Y18: =IF(X18="","",IF(X18>=80%,"Certificado","No certificado")) -> Certificado | Z18: 3.5 | AA18: 4 | AB18: 4 | AC18: =IF(B18="","",IF(AND(X18>=0.8,AB18>=3),"Aprobado","No aprobado")) -> Aprobado | AD18: 5 | AE18: 5 | AF18: 5 | AG18: 5 | AH18: 5 | AI18: 5 | AJ18: 4 | AK18: 5 | AL18: 4 | AM18: 4 | AN18: 5 | AO18: 5 | AP18: 5 | AQ18: 5 | AR18: 5 | AS18: 5 | AT18: 5 | AU18: 5 | AV18: 5 | AW18: 5 | AX18: 5 | AY18: 5 | AZ18: 5 | BA18: 5 | BB18: 5 | BC18: Normatividad vigente | BD18: Más clases presenciales, en lo virtual se distrae mucho el estudiante | BE18: Normatividad vigente | BF18: SI | BG18: 5 | BH18: =AVERAGE(AD18:BG18) -> 4.8846154
A19: 7 | B19: Edwin Hernán Escobar Osorio | C19: 80200994 | D19: Planta | E19: Subdirección de Liquidaciones del Aseguramiento | F19: =_xlfn.XLOOKUP(C19,[1]Hoja1!$B:$B,[1]Hoja1!$F:$F) -> GESTOR DE OPERACIONES | G19: 3 | H19: 2 | I19: 2 | J19: 2 | K19: 2 | L19: 2 | M19: 2 | N19: 2 | O19: 2 | P19: 2 | Q19: 2 | R19: 2 | S19: 2 | T19: 2 | U19: 3 | V19: =IF(B19<>"",SUM(G19:U19),"") -> 32 | W19: =IF(B19<>"",COUNTA(G19:U19),"") -> 15 | X19: =IF(B19<>"",SUM(G19:U19)/32,"") -> 1 | Y19: =IF(X19="","",IF(X19>=80%,"Certificado","No certificado")) -> Certificado | Z19: 4 | AA19: 4 | AB19: 4 | AC19: =IF(B19="","",IF(AND(X19>=0.8,AB19>=3),"Aprobado","No aprobado")) -> Aprobado | AD19: 5 | AE19: 5 | AF19: 5 | AG19: 5 | AH19: 5 | AI19: 5 | AJ19: 5 | AK19: 5 | AL19: 5 | AM19: 5 | AN19: 5 | AO19: 5 | AP19: 5 | AQ19: 5 | AR19: 5 | AS19: 5 | AT19: 5 | AU19: 5 | AV19: 5 | AW19: 5 | AX19: 5 | AY19: 5 | AZ19: 5 | BA19: 5 | BB19: 5 | BC19: La importancia de la transparencia en el sector público | BD19: N/a | BE19: Servicio publico | BF19: SI | BG19: 5 | BH19: =AVERAGE(AD19:BG19) -> 5
A20: 8 | B20: Ernesto Ramírez Virgüez | C20: 80097261 | D20: Planta | E20: Dirección De Gestión De Tecnologías De Información Y Comunicaciones | F20: =_xlfn.XLOOKUP(C20,[1]Hoja1!$B:$B,[1]Hoja1!$F:$F) -> GESTOR DE OPERACIONES | G20: 3 | H20: 2 | I20: 2 | J20: 2 | K20: 2 | L20: 2 | M20: 2 | N20: 2 | O20: 2 | P20: 2 | Q20: 2 | R20: 2 | S20: 2 | T20: 2 | V20: =IF(B20<>"",SUM(G20:U20),"") -> 29 | W20: =IF(B20<>"",COUNTA(G20:U20),"") -> 15 | X20: =IF(B20<>"",SUM(G20:U20)/32,"") -> 0.90625 | Y20: =IF(X20="","",IF(X20>=80%,"Certificado","No certificado")) -> Certificado | Z20: 4.5 | AA20: NP | AB20: 4.5 | AC20: =IF(B20="","",IF(AND(X20>=0.8,AB20>=3),"Aprobado","No aprobado")) -> Aprobado | AD20: 5 | AE20: 5 | AF20: 5 | AG20: 5 | AH20: 5 | AI20: 5 | AJ20: 5 | AK20: 5 | AL20: 5 | AM20: 5 | AN20: 5 | AO20: 5 | AP20: 5 | AQ20: 5 | AR20: 5 | AS20: 5 | AT20: 5 | AU20: 5 | AV20: 5 | AW20: 5 | AX20: 5 | AY20: 5 | AZ20: 5 | BA20: 5 | BB20: 5 | BC20: manejo de procesos disciplinarios | BD20: ninguna | BE20: tecnologia y administracion publica | BF20: SI | BG20: 5 | BH20: =AVERAGE(AD20:BG20) -> 5
A21: 9 | B21: Heidi Patricia Parra Chavarro | C21: 52455010 | D21: Planta | E21: Dirección de Otras Prestaciones | F21: =_xlfn.XLOOKUP(C21,[1]Hoja1!$B:$B,[1]Hoja1!$F:$F) -> GESTOR DE OPERACIONES | G21: 3 | V21: =IF(B21<>"",SUM(G21:U21),"") -> 3 | W21: =IF(B21<>"",COUNTA(G21:U21),"") -> 15 | X21: =IF(B21<>"",SUM(G21:U21)/32,"") -> 0.09375 | Y21: =IF(X21="","",IF(X21>=80%,"Certificado","No certificado")) -> No certificado | Z21: NP | AA21: NP | AB21: 0 | AC21: =IF(B21="","",IF(AND(X21>=0.8,AB21>=3),"Aprobado","No aprobado")) -> No aprobado
A22: 10 | B22: Karen Ginnethe González Sierra | C22: 1030640231 | D22: Planta | E22: Dirección Administrativa y Financiera | F22: =_xlfn.XLOOKUP(C22,[1]Hoja1!$B:$B,[1]Hoja1!$F:$F) -> GESTOR DE OPERACIONES | G22: 3 | H22: 2 | I22: 2 | J22: 2 | K22: 2 | L22: 2 | N22: 2 | O22: 2 | P22: 2 | Q22: 2 | R22: 2 | S22: 2 | T22: 2 | V22: =IF(B22<>"",SUM(G22:U22),"") -> 27 | W22: =IF(B22<>"",COUNTA(G22:U22),"") -> 15 | X22: =IF(B22<>"",SUM(G22:U22)/32,"") -> 0.84375 | Y22: =IF(X22="","",IF(X22>=80%,"Certificado","No certificado")) -> Certificado | Z22: 4 | AA22: 4 | AB22: 4 | AC22: =IF(B22="","",IF(AND(X22>=0.8,AB22>=3),"Aprobado","No aprobado")) -> Aprobado | AD22: 5 | AE22: 5 | AF22: 5 | AG22: 5 | AH22: 5 | AI22: 5 | AJ22: 5 | AK22: 5 | AL22: 5 | AM22: 5 | AN22: 5 | AO22: 5 | AP22: 5 | AQ22: 5 | AR22: 5 | AS22: 5 | AT22: 5 | AU22: 5 | AV22: 5 | AW22: 5 | AX22: 5 | AY22: 5 | AZ22: 5 | BA22: 5 | BB22: 5 | BC22: N/A | BD22: Tener mas tiempo para poder revisar mas a fondo todo lo visto | BE22: Seguir mirando la Gestión Pública que es muy amplia | BF22: SI | BG22: 5 | BH22: =AVERAGE(AD22:BG22) -> 5
A23: 11 | B23: Lorena Fabiola Amézquita Becerra | C23: 46458408 | D23: Planta | E23: Dirección de Otras Prestaciones | F23: =_xlfn.XLOOKUP(C23,[1]Hoja1!$B:$B,[1]Hoja1!$F:$F) -> GESTOR DE OPERACIONES | G23: 3 | H23: 2 | I23: 2 | J23: 2 | L23: 2 | M23: 2 | N23: 2 | O23: 2 | P23: 2 | Q23: 2 | R23: 2 | S23: 2 | T23: 2 | V23: =IF(B23<>"",SUM(G23:U23),"") -> 27 | W23: =IF(B23<>"",COUNTA(G23:U23),"") -> 15 | X23: =IF(B23<>"",SUM(G23:U23)/32,"") -> 0.84375 | Y23: =IF(X23="","",IF(X23>=80%,"Certificado","No certificado")) -> Certificado | Z23: 4 | AA23: 4 | AB23: 4 | AC23: =IF(B23="","",IF(AND(X23>=0.8,AB23>=3),"Aprobado","No aprobado")) -> Aprobado | AD23: 5 | AE23: 5 | AF23: 5 | AG23: 5 | AH23: 5 | AI23: 5 | AJ23: 5 | AK23: 5 | AL23: 5 | AM23: 5 | AN23: 5 | AO23: 5 | AP23: 5 | AQ23: 5 | AR23: 5 | AS23: 5 | AT23: 5 | AU23: 5 | AV23: 5 | AW23: 5 | AX23: 5 | AY23: 5 | AZ23: 5 | BA23: 5 | BB23: 5 | BC23: Ninguno | BD23: Ninguna | BE23: Ninguna | BF23: SI | BG23: 5 | BH23: =AVERAGE(AD23:BG23) -> 5
A24: 12 | B24: María Claudia López Calle | C24: 43016375 | D24: Planta | E24: Dirección Administrativa y Financiera | F24: =_xlfn.XLOOKUP(C24,[1]Hoja1!$B:$B,[1]Hoja1!$F:$F) -> GESTOR DE OPERACIONES | G24: 3 | H24: 2 | I24: 2 | J24: 2 | K24: 2 | L24: 2 | M24: 2 | N24: 2 | O24: 2 | P24: 2 | Q24: 2 | R24: 2 | S24: 2 | T24: 2 | U24: 3 | V24: =IF(B24<>"",SUM(G24:U24),"") -> 32 | W24: =IF(B24<>"",COUNTA(G24:U24),"") -> 15 | X24: =IF(B24<>"",SUM(G24:U24)/32,"") -> 1 | Y24: =IF(X24="","",IF(X24>=80%,"Certificado","No certificado")) -> Certificado | Z24: 4 | AA24: NP | AB24: 4 | AC24: =IF(B24="","",IF(AND(X24>=0.8,AB24>=3),"Aprobado","No aprobado")) -> Aprobado | AD24: 5 | AE24: 5 | AF24: 5 | AG24: 5 | AH24: 5 | AI24: 5 | AJ24: 4 | AK24: 4 | AL24: 3 | AM24: 4 | AN24: 4 | AO24: 4 | AP24: 5 | AQ24: 5 | AR24: 5 | AS24: 5 | AT24: 5 | AU24: 4 | AV24: 5 | AW24: 5 | AX24: 5 | AY24: 5 | AZ24: 5 | BA24: 5 | BB24: 5 | BC24: Concientizar a mas servidores públicos, asesores, directores, mas del alto mando, quienes son los ordenadores del gasto. sobre la transparencia y gestión de las entidades. | BD24: Dictar el curso de acuerdo a lo anterior dicho | BE24: Mas temas jurídicos | BF24: SI | BG24: 4 | BH24: =AVERAGE(AD24:BG24) -> 4.6538462
A25: 13 | B25: Martha Roció Montoya Sarmiento | C25: 52318058 | D25: Planta | E25: Dirección De Gestión De Tecnologías De Información Y Comunicaciones | F25: =_xlfn.XLOOKUP(C25,[1]Hoja1!$B:$B,[1]Hoja1!$F:$F) -> AUXILIAR ADMINISTRATIVO | V25: =IF(B25<>"",SUM(G25:U25),"") -> 0 | W25: =IF(B25<>"",COUNTA(G25:U25),"") -> 15 | X25: =IF(B25<>"",SUM(G25:U25)/32,"") -> 0 | Y25: =IF(X25="","",IF(X25>=80%,"Certificado","No certificado")) -> No certificado | Z25: NP | AA25: NP | AB25: 0 | AC25: =IF(B25="","",IF(AND(X25>=0.8,AB25>=3),"Aprobado","No aprobado")) -> No aprobado
A26: 14 | B26: Mayury Vanegas González | C26: 52315691 | D26: Planta | E26: Subdirección de Liquidaciones del Aseguramiento | F26: =_xlfn.XLOOKUP(C26,[1]Hoja1!$B:$B,[1]Hoja1!$F:$F) -> GESTOR DE OPERACIONES | H26: 2 | I26: 2 | J26: 2 | K26: 2 | L26: 2 | M26: 2 | N26: 2 | O26: 2 | P26: 2 | Q26: 2 | R26: 2 | S26: 2 | T26: 2 | U26: 3 | V26: =IF(B26<>"",SUM(G26:U26),"") -> 29 | W26: =IF(B26<>"",COUNTA(G26:U26),"") -> 15 | X26: =IF(B26<>"",SUM(G26:U26)/32,"") -> 0.90625 | Y26: =IF(X26="","",IF(X26>=80%,"Certificado","No certificado")) -> Certificado | Z26: 4 | AA26: 4 | AB26: 4 | AC26: =IF(B26="","",IF(AND(X26>=0.8,AB26>=3),"Aprobado","No aprobado")) -> Aprobado | AD26: 5 | AE26: 5 | AF26: 5 | AG26: 5 | AH26: 5 | AI26: 5 | AJ26: 5 | AK26: 5 | AL26: 5 | AM26: 5 | AN26: 5 | AO26: 5 | AP26: 5 | AQ26: 5 | AR26: 5 | AS26: 5 | AT26: 5 | AU26: 5 | AV26: 5 | AW26: 5 | AX26: 5 | AY26: 5 | AZ26: 5 | BA26: 5 | BB26: 5 | BC26: mpig | BD26: retirar la metodologia de puntos, me parece q incentivar la participación | BE26: sistemas | BF26: SI | BG26: 5 | BH26: =AVERAGE(AD26:BG26) -> 5
A27: 15 | B27: Miller Alexander Reina Escobar | C27: 70663332 | D27: Planta | E27: Dirección de Otras Prestaciones | F27: =_xlfn.XLOOKUP(C27,[1]Hoja1!$B:$B,[1]Hoja1!$F:$F) -> GESTOR DE OPERACIONES | G27: 3 | H27: 2 | I27: 2 | J27: 2 | K27: 2 | L27: 2 | M27: 2 | N27: 2 | O27: 2 | P27: 2 | Q27: 2 | R27: 2 | S27: 2 | T27: 2 | U27: 3 | V27: =IF(B27<>"",SUM(G27:U27),"") -> 32 | W27: =IF(B27<>"",COUNTA(G27:U27),"") -> 15 | X27: =IF(B27<>"",SUM(G27:U27)/32,"") -> 1 | Y27: =IF(X27="","",IF(X27>=80%,"Certificado","No certificado")) -> Certificado | Z27: 3.5 | AA27: 4 | AB27: 4 | AC27: =IF(B27="","",IF(AND(X27>=0.8,AB27>=3),"Aprobado","No aprobado")) -> Aprobado | AD27: 5 | AE27: 5 | AF27: 4 | AG27: 4 | AH27: 5 | AI27: 5 | AJ27: 4 | AK27: 4 | AL27: 3 | AM27: 4 | AN27: 4 | AO27: 4 | AP27: 5 | AQ27: 5 | AR27: 5 | AS27: 5 | AT27: 5 | AU27: 5 | AV27: 5 | AW27: 5 | AX27: 5 | AY27: 5 | AZ27: 5 | BA27: 5 | BB27: 5 | BC27: n/a | BD27: n/a | BE27: Inteligencia artificial, analisis de datos y supervisión contractual del estado | BF27: SI | BG27: 5 | BH27: =AVERAGE(AD27:BG27) -> 4.6538462
A28: 16 | B28: Nancy Esperanza Villamil Cifuentes | C28: 52454760 | D28: Planta | E28: Oficina Asesora de Planeación y Control de Riesgos | F28: =_xlfn.XLOOKUP(C28,[1]Hoja1!$B:$B,[1]Hoja1!$F:$F) -> GESTOR DE OPERACIONES | G28: 3 | H28: 2 | I28: 2 | J28: 2 | K28: 2 | L28: 2 | M28: 2 | N28: 2 | O28: 2 | P28: 2 | Q28: 2 | R28: 2 | S28: 2 | T28: 2 | U28: 3 | V28: =IF(B28<>"",SUM(G28:U28),"") -> 32 | W28: =IF(B28<>"",COUNTA(G28:U28),"") -> 15 | X28: =IF(B28<>"",SUM(G28:U28)/32,"") -> 1 | Y28: =IF(X28="","",IF(X28>=80%,"Certificado","No certificado")) -> Certificado | Z28: 4.5 | AA28: 4 | AB28: 4.5 | AC28: =IF(B28="","",IF(AND(X28>=0.8,AB28>=3),"Aprobado","No aprobado")) -> Aprobado | AD28: 5 | AE28: 5 | AF28: 5 | AG28: 5 | AH28: 5 | AI28: 5 | AJ28: 5 | AK28: 5 | AL28: 5 | AM28: 5 | AN28: 5 | AO28: 5 | AP28: 5 | AQ28: 5 | AR28: 5 | AS28: 5 | AT28: 5 | AU28: 5 | AV28: 5 | AW28: 5 | AX28: 5 | AY28: 5 | AZ28: 5 | BA28: 5 | BB28: 5 | BC28: Ampliación en la Normatividad sobre el tema de corrupción | BD28: Ninguna, la metodología utilizada es muy buena sin embargo la intensidad horaria debería ser más amplia. | BE28: Bases de datos, atención al cuidadano, comunicación asertiva, Mipg | BF28: SI | BG28: 5 | BH28: =AVERAGE(AD28:BG28) -> 5
A29: 17 | B29: Nathaly Constanza Alvarado Núñez | C29: 1015415271 | D29: Planta | E29: Oficina Asesora Jurídica | F29: =_xlfn.XLOOKUP(C29,[1]Hoja1!$B:$B,[1]Hoja1!$F:$F) -> GESTOR DE OPERACIONES | G29: 3 | H29: 2 | I29: 2 | J29: 2 | K29: 2 | L29: 2 | M29: 2 | N29: 2 | O29: 2 | P29: 2 | Q29: 2 | R29: 2 | S29: 2 | T29: 2 | U29: 3 | V29: =IF(B29<>"",SUM(G29:U29),"") -> 32 | W29: =IF(B29<>"",COUNTA(G29:U29),"") -> 15 | X29: =IF(B29<>"",SUM(G29:U29)/32,"") -> 1 | Y29: =IF(X29="","",IF(X29>=80%,"Certificado","No certificado")) -> Certificado | Z29: 3.5 | AA29: 3.5 | AB29: 4.5 | AC29: =IF(B29="","",IF(AND(X29>=0.8,AB29>=3),"Aprobado","No aprobado")) -> Aprobado | AD29: 5 | AE29: 5 | AF29: 5 | AG29: 5 | AH29: 5 | AI29: 5 | AJ29: 4 | AK29: 4 | AL29: 4 | AM29: 4 | AN29: 4 | AO29: 4 | AP29: 5 | AQ29: 5 | AR29: 5 | AS29: 5 | AT29: 5 | AU29: 5 | AV29: 5 | AW29: 5 | AX29: 5 | AY29: 5 | AZ29: 5 | BA29: 5 | BB29: 5 | BC29: el tema de la UIAF | BD29: fueron muy completas | BE29: sobre la gestión de conocimiento | BF29: SI | BG29: 5 | BH29: =AVERAGE(AD29:BG29) -> 4.7692308
A30: 18 | B30: Teodolinda Sánchez Delgado | C30: 28977244 | D30: Planta | E30: Oficina de Control Interno | F30: =_xlfn.XLOOKUP(C30,[1]Hoja1!$B:$B,[1]Hoja1!$F:$F) -> GESTOR DE OPERACIONES | G30: 3 | H30: 2 | I30: 2 | J30: 2 | K30: 2 | L30: 2 | M30: 2 | N30: 2 | O30: 2 | P30: 2 | Q30: 2 | R30: 2 | S30: 2 | T30: 2 | V30: =IF(B30<>"",SUM(G30:U30),"") -> 29 | W30: =IF(B30<>"",COUNTA(G30:U30),"") -> 15 | X30: =IF(B30<>"",SUM(G30:U30)/32,"") -> 0.90625 | Y30: =IF(X30="","",IF(X30>=80%,"Certificado","No certificado")) -> Certificado | Z30: 4 | AA30: 3.5 | AB30: 4 | AC30: =IF(B30="","",IF(AND(X30>=0.8,AB30>=3),"Aprobado","No aprobado")) -> Aprobado | AD30: 5 | AE30: 5 | AF30: 5 | AG30: 5 | AH30: 5 | AI30: 5 | AJ30: 4 | AK30: 4 | AL30: 4 | AM30: 4 | AN30: 4 | AO30: 4 | AP30: 5 | AQ30: 5 | AR30: 5 | AS30: 5 | AT30: 5 | AU30: 5 | AV30: 5 | AW30: 5 | AX30: 5 | AY30: 5 | AZ30: 5 | BA30: 5 | BB30: 5 | BC30: Power be | BD30: N/A | BE30: Bases de datos | BF30: SI | BG30: 5 | BH30: =AVERAGE(AD30:BG30) -> 4.7692308
A31: 19 | B31: Yuly Andrea Gómez Gutiérrez | C31: 52528416 | D31: Planta | E31: Dirección Administrativa y Financiera | F31: =_xlfn.XLOOKUP(C31,[1]Hoja1!$B:$B,[1]Hoja1!$F:$F) -> GESTOR DE OPERACIONES | G31: 3 | H31: 2 | I31: 2 | J31: 2 | K31: 2 | L31: 2 | M31: 2 | N31: 2 | O31: 2 | P31: 2 | Q31: 2 | R31: 2 | T31: 2 | V31: =IF(B31<>"",SUM(G31:U31),"") -> 27 | W31: =IF(B31<>"",COUNTA(G31:U31),"") -> 15 | X31: =IF(B31<>"",SUM(G31:U31)/32,"") -> 0.84375 | Y31: =IF(X31="","",IF(X31>=80%,"Certificado","No certificado")) -> Certificado | Z31: 4 | AA31: NP | AB31: 4 | AC31: =IF(B31="","",IF(AND(X31>=0.8,AB31>=3),"Aprobado","No aprobado")) -> Aprobado | AD31: 5 | AE31: 5 | AF31: 5 | AG31: 5 | AH31: 5 | AI31: 5 | AJ31: 5 | AK31: 5 | AL31: 5 | AM31: 5 | AN31: 5 | AO31: 5 | AP31: 5 | AQ31: 5 | AR31: 5 | AS31: 5 | AT31: 5 | AU31: 5 | AV31: 5 | AW31: 5 | AX31: 5 | AY31: 5 | AZ31: 5 | BA31: 5 | BB31: 5 | BC31: NA | BD31: NA | BE31: PRESUPUETSO | BF31: SI | BG31: 5 | BH31: =AVERAGE(AD31:BG31) -> 5
A32: Observaciones:

Sheet 5 - Atención diferencial
A1: UNIDAD DE EDUCACIÓN CONTINUA FACULTAD DE INGENIERÍA | W1: VERSIÓN 1.0
W3: PÁGINA 1 DE 1
A5: FACULTAD INGENIERÍA UNAL
A6: PROCESO: DESARROLLO DE LAS MODALIDADES DE EXTENSIÓN
A7: NOMBRE DEL CURSO, DIPLOMADO O PROYECTO
A8: CURSO "ATENCIÓN DIFERENCIAL Y COMUNICACIÓN EFECTIVA"
A9: NOMBRE DEL PROFESOR | E9: ='Formato Cronograma'!F8 -> Olga Lucía Quintero Sierra | G9: N° S.PRESENCIALES(SP) | O9: N° S.VIRTUALES SINCRÓNICAS(VS) | U9: NOMBRE DEL MONITOR | Y9: DANIEL FELIPE CRUZ SAENZ
A10: FECHA DE INICIO | C10: ='Formato Cronograma'!K8 -> 46097 | D10: FECHA DE FIN | F10: ='Formato Cronograma'!L8 -> 46150 | G10: 2 | O10: 12 | U10: HORAS DEL CURSO | W10: 32 | Y10: CÓDIGO HERMES | AC10: ENCUESTA
A11: INFORMACIÓN DEL ESTUDIANTE | G11: SESIONES | U11: ASISTENCIA | Y11: NOTAS | AC11: ENCUESTA - DOCENTE | AI11: ENCUESTA - MONITOR | AL11: ENCUESTA - LOGÍSTICA | AV11: ENCUESTA - PREGUNTAS ABIERTAS | BA11: TOTAL
A12: NO | B12: NOMBRE Y APELLIDOS | C12: DOCUMENTO | D12: TIPO DE VINCULACIÓN CON LA ENTIDAD | E12: ÁREA A LA QUE PERTENECE | F12: NOMBRE DEL CARGO | G12: 1 | H12: 2 | I12: 3 | J12: 4 | K12: 5 | L12: 6 | M12: 7 | N12: 8 | O12: 9 | P12: 10 | Q12: 11 | R12: 12 | S12: 13 | T12: 14 | U12: HORAS ACUMULADAS | V12: SESIONES ASISTIDAS | W12: % ASISTENCIA | X12: ¿CUMPLE ASISTENCIA? | Y12: PRE | Z12: POST | AA12: FINAL | AB12: APROBACIÓN | AC12: 1,1 El cumplimiento de los objetivos y desarrollo del contenido de la actividad fue | AD12: 1,2 Actualización en el área | AE12: 1,3 Capacidad para comunicar ideas | AF12: 1,4 Pertinencia de la metodología empleada | AG12: 1,5 Cumplimiento de los horarios previstos en el cronograma de la actividad | AH12: 1,6 Conocimiento y dominio de los temas | AI12: 2,1 Apoyo al conferencista y asistentes en las tareas previstas en la actividad | AJ12: 2,2 Acompañamiento en cada una de las sesiones de la actividad | AK12: 2,3 Disposición y actitud frente a los asistentes | AL12: 3,1 Contenido del material suministrado | AM12: 3,2 Presentación del material suministrado | AN12: 3,3 Atención de refrigerios | AO12: 3,4 Instalaciones Físicas | AP12: 3,5 Ayudas audiovisuales | AQ12: 3,6 Atención en el proceso de inscripción | AR12: 3,7 Disponibilidad del aula virtual | AS12: 3,8 Contacto con el docente | AT12: 3,9 Pertinencia del material dispuesto en la plataforma | AU12: 3,10 Manejo de las herramientas digitales | AV12: 4,1 ¿Qué temas considera necesarios profundizar en este actividad? | AW12: 4,2 ¿Qué recomendaciones haría para mejorar las actividades? | AX12: 4,3 ¿En qué áreas desearía obtener información y/o actualización a través de las actividades de Educación Continua y Permanente? | AY12: 4,4 ¿Asistiría a otra actividad programada por nosotros? | AZ12: 4,5 ¿La actividad fue satisfactoria? | BA12: Promedio
A13: 1 | B13: Carlos Felipe Rodríguez Ordoñez | C13: 79943655 | D13: Planta | E13: Dirección De Gestión De Tecnologías De Información Y Comunicaciones | F13: Gestor De Operaciones | U13: =IF(B13<>"",SUM(G13:T13),"") -> 0 | V13: =IF(B13<>"",COUNTA(G13:T13),"") -> 0 | W13: =IF(B13<>"",SUM(G13:T13)/32,"") -> 0 | X13: =IF(W13="","",IF(W13>=80%,"Certificado","No certificado")) -> No certificado | AB13: =IF(B13="","",IF(AND(W13>=0.8,AA13>=3),"Aprobado","No aprobado")) -> No aprobado
A14: 2 | B14: Herber Smith Romero Martínez | C14: 79893474 | D14: Planta | E14: Dirección De Liquidaciones Y Garantías | F14: Gestor De Operaciones | G14: 3 | H14: 2 | I14: 2 | J14: 2 | K14: 2 | L14: 2 | M14: 2 | N14: 2 | O14: 2 | P14: 2 | Q14: 2 | R14: 2 | S14: 2 | T14: 5 | U14: =IF(B14<>"",SUM(G14:T14),"") -> 32 | V14: =IF(B14<>"",COUNTA(G14:T14),"") -> 14 | W14: =IF(B14<>"",SUM(G14:T14)/32,"") -> 1 | X14: =IF(W14="","",IF(W14>=80%,"Certificado","No certificado")) -> Certificado | Y14: 5 | Z14: 4 | AA14: 4.7 | AB14: =IF(B14="","",IF(AND(W14>=0.8,AA14>=3),"Aprobado","No aprobado")) -> Aprobado | AC14: 5 | AD14: 5 | AE14: 5 | AF14: 5 | AG14: 5 | AH14: 5 | AI14: 5 | AJ14: 5 | AK14: 5 | AL14: 5 | AM14: 5 | AN14: 5 | AO14: 5 | AP14: 5 | AQ14: 5 | AR14: 5 | AS14: 5 | AT14: 5 | AU14: 5 | AV14: se pudieran profundizar un poco más los temas en algunos casos el tiempo se queda corto | AW14: en este curso un poco mas de intensidad horaria | AX14: en atención al cliente | AY14: SI | AZ14: 5 | BA14: =AVERAGE(Tabla_AtnDiferencial[[#This Row],[1,1 El cumplimiento de los objetivos y desarrollo del contenido de la actividad fue]:[4,5 ¿La actividad fue satisfactoria?]]) -> 5
A15: 3 | B15: Kris Jeniffer Vargas Reyes | C15: 53121904 | D15: Planta | E15: Subdirección De Liquidaciones Del Aseguramiento | F15: Gestor De Operaciones | G15: 3 | H15: 2 | I15: 2 | J15: 2 | K15: 2 | L15: 2 | M15: 2 | N15: 2 | O15: 2 | P15: 2 | Q15: 2 | R15: 2 | S15: 2 | T15: 5 | U15: =IF(B15<>"",SUM(G15:T15),"") -> 32 | V15: =IF(B15<>"",COUNTA(G15:T15),"") -> 14 | W15: =IF(B15<>"",SUM(G15:T15)/32,"") -> 1 | X15: =IF(W15="","",IF(W15>=80%,"Certificado","No certificado")) -> Certificado | Y15: 3 | Z15: 5 | AA15: 4.7 | AB15: =IF(B15="","",IF(AND(W15>=0.8,AA15>=3),"Aprobado","No aprobado")) -> Aprobado | AC15: 5 | AD15: 5 | AE15: 5 | AF15: 4 | AG15: 4 | AH15: 5 | AI15: 5 | AJ15: 5 | AK15: 5 | AL15: 5 | AM15: 5 | AN15: 4 | AO15: 5 | AP15: 4 | AQ15: 4 | AR15: 5 | AS15: 5 | AT15: 5 | AU15: 5 | AV15: La formación debería tener mayor frecuencia, aporta mucho al desarrollo personal y esto impacta en el ámbito laboral. | AW15: La presencialidad debería aumentarse para poder tener mayor participación grupal. Estar en la oficina distrae y sigue siendo un reto disponer tiempo completo para estas actividades. | AX15: Desarrollo Humano y Herramientas para mejorar las relaciones interpersonales. | AY15: SI | AZ15: 5 | BA15: =AVERAGE(Tabla_AtnDiferencial[[#This Row],[1,1 El cumplimiento de los objetivos y desarrollo del contenido de la actividad fue]:[4,5 ¿La actividad fue satisfactoria?]]) -> 4.75
A16: 4 | B16: Lizeth Julieth Gordillo Góngora | C16: 1136882430 | D16: Planta | E16: Dirección Administrativa Y Financiera | F16: Técnico Administrativo | G16: 3 | H16: 2 | J16: 2 | K16: 2 | L16: 2 | M16: 2 | O16: 2 | P16: 2 | Q16: 2 | S16: 2 | T16: 5 | U16: =IF(B16<>"",SUM(G16:T16),"") -> 26 | V16: =IF(B16<>"",COUNTA(G16:T16),"") -> 11 | W16: =IF(B16<>"",SUM(G16:T16)/32,"") -> 0.8125 | X16: =IF(W16="","",IF(W16>=80%,"Certificado","No certificado")) -> Certificado | AA16: 4.4 | AB16: =IF(B16="","",IF(AND(W16>=0.8,AA16>=3),"Aprobado","No aprobado")) -> Aprobado
